<?xml version="1.0" encoding="utf-8"?>
<!-- This URDF was automatically created by SolidWorks to URDF Exporter! Originally created by Stephen Brawner (brawner@gmail.com) 
     Commit Version: 1.6.0-4-g7f85cfe  Build Version: 1.6.7995.38578
     For more information, please see http://wiki.ros.org/sw_urdf_exporter -->
<robot
  name="rover">
  <link
    name="base_link">
    <inertial>
      <origin
        xyz="0.0525974995543178 -0.000194464834775451 -0.0100913190853692"
        rpy="0 0 0" />
      <mass
        value="2.38375982168779" />
      <inertia
        ixx="0.0206956872468266"
        ixy="5.63024158022762E-09"
        ixz="0.000212908082281701"
        iyy="0.0144158206994705"
        iyz="-1.03954167908993E-08"
        izz="0.0347891159880286" />
    </inertial>
    <visual>
      <origin
        xyz="0 0 0"
        rpy="0 0 0" />
      <geometry>
        <mesh
          filename="package://rover/meshes/base_link.STL" />
      </geometry>
      <material
        name="">
        <color
          rgba="0.752941176470588 0.752941176470588 0.752941176470588 1" />
      </material>
    </visual>
    <collision>
      <origin
        xyz="0 0 0"
        rpy="0 0 0" />
      <geometry>
        <mesh
          filename="package://rover/meshes/base_link.STL" />
      </geometry>
    </collision>
  </link>
  <link
    name="wheel_left">
    <inertial>
      <origin
        xyz="2.4980018054066E-16 0.494569432322382 2.04003480774873E-15"
        rpy="0 0 0" />
      <mass
        value="0.822414833099408" />
      <inertia
        ixx="0.00292595796569318"
        ixy="-4.70537025297137E-19"
        ixz="-1.54115754149799E-33"
        iyy="0.00542762830860089"
        iyz="9.52641887370321E-18"
        izz="0.00292595796569318" />
    </inertial>
    <visual>
      <origin
        xyz="0 0 0"
        rpy="0 0 0" />
      <geometry>
        <mesh
          filename="package://rover/meshes/wheel_left.STL" />
      </geometry>
      <material
        name="">
        <color
          rgba="0.752941176470588 0.752941176470588 0.752941176470588 1" />
      </material>
    </visual>
    <collision>
      <origin
        xyz="0 0 0"
        rpy="0 0 0" />
      <geometry>
        <mesh
          filename="package://rover/meshes/wheel_left.STL" />
      </geometry>
    </collision>
  </link>
  <joint
    name="j_wheel_left"
    type="continuous">
    <origin
      xyz="0.125 -0.247 -0.0299999999999999"
      rpy="0 0 0" />
    <parent
      link="base_link" />
    <child
      link="wheel_left" />
    <axis
      xyz="0 -1 0" />
  </joint>
  <link
    name="wheel_right">
    <inertial>
      <origin
        xyz="-3.46944695195361E-16 -0.494569432322382 -1.56125112837913E-16"
        rpy="0 0 0" />
      <mass
        value="0.822414833099408" />
      <inertia
        ixx="0.00292595796569318"
        ixy="4.75322584588116E-19"
        ixz="-1.93796700653966E-33"
        iyy="0.00542762830860089"
        iyz="-9.54453148980118E-18"
        izz="0.00292595796569318" />
    </inertial>
    <visual>
      <origin
        xyz="0 0 0"
        rpy="0 0 0" />
      <geometry>
        <mesh
          filename="package://rover/meshes/wheel_right.STL" />
      </geometry>
      <material
        name="">
        <color
          rgba="0.752941176470588 0.752941176470588 0.752941176470588 1" />
      </material>
    </visual>
    <collision>
      <origin
        xyz="0 0 0"
        rpy="0 0 0" />
      <geometry>
        <mesh
          filename="package://rover/meshes/wheel_right.STL" />
      </geometry>
    </collision>
  </link>
  <joint
    name="j_wheel_right"
    type="continuous">
    <origin
      xyz="0.125 0.247 -0.0299999999999979"
      rpy="0 0 0" />
    <parent
      link="base_link" />
    <child
      link="wheel_right" />
    <axis
      xyz="0 -1 0" />
  </joint>
  <link
    name="caster_link">
    <inertial>
      <origin
        xyz="-0.0104577729094667 -1.70972644986437E-06 -0.0348997239505959"
        rpy="0 0 0" />
      <mass
        value="0.328375253608877" />
      <inertia
        ixx="0.000340045444422583"
        ixy="9.1850194938355E-09"
        ixz="-9.80776230870345E-05"
        iyy="0.000352874912673895"
        iyz="-6.46363627390862E-09"
        izz="0.000225098721857176" />
    </inertial>
    <visual>
      <origin
        xyz="0 0 0"
        rpy="0 0 0" />
      <geometry>
        <mesh
          filename="package://rover/meshes/caster_link.STL" />
      </geometry>
      <material
        name="">
        <color
          rgba="0.647058823529412 0.619607843137255 0.588235294117647 1" />
      </material>
    </visual>
    <collision>
      <origin
        xyz="0 0 0"
        rpy="0 0 0" />
      <geometry>
        <mesh
          filename="package://rover/meshes/caster_link.STL" />
      </geometry>
    </collision>
  </link>
  <joint
    name="j_caster_link"
    type="continuous">
    <origin
      xyz="-0.14610625 0 -0.026825"
      rpy="0 0 -0.000559241919372657" />
    <parent
      link="base_link" />
    <child
      link="caster_link" />
    <axis
      xyz="0 0 1" />
  </joint>
  <link
    name="wheel_rear">
    <inertial>
      <origin
        xyz="2.77555756156289E-17 3.00866102864727E-18 0"
        rpy="0 0 0" />
      <mass
        value="0.244317433446432" />
      <inertia
        ixx="0.000169301711020207"
        ixy="5.11528490802792E-21"
        ixz="6.11428746179974E-21"
        iyy="0.000304051252450228"
        iyz="-1.77398397427055E-21"
        izz="0.000169301711020207" />
    </inertial>
    <visual>
      <origin
        xyz="0 0 0"
        rpy="0 0 0" />
      <geometry>
        <mesh
          filename="package://rover/meshes/wheel_rear.STL" />
      </geometry>
      <material
        name="">
        <color
          rgba="0.647058823529412 0.619607843137255 0.588235294117647 1" />
      </material>
    </visual>
    <collision>
      <origin
        xyz="0 0 0"
        rpy="0 0 0" />
      <geometry>
        <mesh
          filename="package://rover/meshes/wheel_rear.STL" />
      </geometry>
    </collision>
  </link>
  <joint
    name="j_wheel_rear"
    type="continuous">
    <origin
      xyz="-0.0309499 0 -0.079375"
      rpy="0 0 0" />
    <parent
      link="caster_link" />
    <child
      link="wheel_rear" />
    <axis
      xyz="0 -1 0" />
  </joint>
</robot>
